Workbook

Sheet Gráficos

Sheet 1. Ramos Totales
A1: Sector Asegurador Hondureño
A2: Situación de Primas y Siniestros por Ramo
A3: Al 31 de diciembre de 2025
A4: (Valores en millones de Lempiras y Porcentajes)
A6: 1. Ramos Totales
A8: Rubro | B8: PRIMAS | F8: SINIESTROS | J8: Siniestros/Primas | N8: Participación de mercado
B9: 45657 | C9: 46022 | D9: Relativa | E9: Absoluta | F9: =B9 -> 45657 | G9: =C9 -> 46022 | H9: Relativa | I9: Absoluta | J9: =B9 -> 45657 | K9: =C9 -> 46022 | L9: Relativa | M9: Absoluta | N9: =B9 -> 45657 | O9: =C9 -> 46022 | P9: Relativa | Q9: Absoluta
A10: Vida | B10: ='Primas Diciembre 2024'!D51/1000 -> 6507.7859 | C10: ='Primas Diciembre 2025'!B51/1000 -> 6900.9688 | D10: =IFERROR(E10/B10,0%) -> 0.060417307 | E10: =IFERROR(C10-B10,0) -> 393.1829 | F10: ='Siniestros Diciembre 2024'!E51/1000 -> 1797.332 | G10: ='Siniestros Diciembre 2025'!B51/1000 -> 2010.424 | H10: =IFERROR(I10/F10,0%) -> 0.1185602 | I10: =IFERROR(G10-F10,0) -> 213.09203 | J10: =IFERROR((F10/B10),0%) -> 0.27618179 | K10: =IFERROR(G10/C10,0%) -> 0.2913249 | L10: =IFERROR(M10/J10,0%) -> 0.054830195 | M10: =K10-J10 -> 0.015143102 | N10: =B10/$B$21 -> 0.35288353 | O10: =C10/$C$21 -> 0.3419413 | P10: =IFERROR(Q10/N10,0%) -> -0.031008044 | Q10: =IFERROR(O10-N10,0) -> -0.010942228
A11: Vida Individual | B11: ='Primas Diciembre 2024'!D55/1000 -> 904.40902 | C11: ='Primas Diciembre 2025'!B55/1000 -> 957.52387 | D11: =IFERROR(E11/B11,0%) -> 0.058728791 | E11: =IFERROR(C11-B11,0) -> 53.114848 | F11: ='Siniestros Diciembre 2024'!E55/1000 -> 196.62319 | G11: ='Siniestros Diciembre 2025'!B55/1000 -> 272.35245 | H11: =IFERROR(I11/F11,0%) -> 0.38514916 | I11: =IFERROR(G11-F11,0) -> 75.729258 | J11: =IFERROR((F11/B11),0%) -> 0.21740517 | K11: =IFERROR(G11/C11,0%) -> 0.28443411 | L11: =IFERROR(M11/J11,0%) -> 0.30831349 | M11: =K11-J11 -> 0.067028946 | N11: =B11/$B$21 -> 0.049041417 | O11: =C11/$C$21 -> 0.047445071 | P11: =IFERROR(Q11/N11,0%) -> -0.032550983 | Q11: =IFERROR(O11-N11,0) -> -0.0015963463
A12: Vida Colectivo | B12: ='Primas Diciembre 2024'!D54/1000 -> 5589.6173 | C12: ='Primas Diciembre 2025'!B54/1000 -> 5929.7598 | D12: =IFERROR(E12/B12,0%) -> 0.060852565 | E12: =IFERROR(C12-B12,0) -> 340.14255 | F12: ='Siniestros Diciembre 2024'!E54/1000 -> 1590.688 | G12: ='Siniestros Diciembre 2025'!B54/1000 -> 1729.9776 | H12: =IFERROR(I12/F12,0%) -> 0.087565582 | I12: =IFERROR(G12-F12,0) -> 139.28952 | J12: =IFERROR((F12/B12),0%) -> 0.28457906 | K12: =IFERROR(G12/C12,0%) -> 0.29174497 | L12: =IFERROR(M12/J12,0%) -> 0.025180706 | M12: =K12-J12 -> 0.0071659017 | N12: =B12/$B$21 -> 0.303096 | O12: =C12/$C$21 -> 0.29381813 | P12: =IFERROR(Q12/N12,0%) -> -0.030610313 | Q12: =IFERROR(O12-N12,0) -> -0.0092778632
A13: Accidentes y Enfermedades | B13: ='Primas Diciembre 2024'!D12/1000 -> 3667.9374 | C13: ='Primas Diciembre 2025'!B12/1000 -> 4050.0066 | D13: =IFERROR(E13/B13,0%) -> 0.10416457 | E13: =IFERROR(C13-B13,0) -> 382.06912 | F13: ='Siniestros Diciembre 2024'!E12/1000 -> 2523.8946 | G13: ='Siniestros Diciembre 2025'!B12/1000 -> 2764.2953 | H13: =IFERROR(I13/F13,0%) -> 0.095249906 | I13: =IFERROR(G13-F13,0) -> 240.40072 | J13: =IFERROR((F13/B13),0%) -> 0.68809641 | K13: =IFERROR(G13/C13,0%) -> 0.68254094 | L13: =IFERROR(M13/J13,0%) -> -0.0080736723 | M13: =K13-J13 -> -0.0055554649 | N13: =B13/$B$21 -> 0.19889325 | O13: =C13/$C$21 -> 0.20067682 | P13: =IFERROR(Q13/N13,0%) -> 0.0089674863 | Q13: =IFERROR(O13-N13,0) -> 0.0017835725
A14: Accidentes Personales | B14: ='Primas Diciembre 2024'!D14/1000 -> 413.14882 | C14: ='Primas Diciembre 2025'!B14/1000 -> 510.89209 | D14: =IFERROR(E14/B14,0%) -> 0.23658127 | E14: =IFERROR(C14-B14,0) -> 97.743271 | F14: ='Siniestros Diciembre 2024'!E14/1000 -> 76.625171 | G14: ='Siniestros Diciembre 2025'!B14/1000 -> 92.908461 | H14: =IFERROR(I14/F14,0%) -> 0.21250576 | I14: =IFERROR(G14-F14,0) -> 16.28329 | J14: =IFERROR((F14/B14),0%) -> 0.18546627 | K14: =IFERROR(G14/C14,0%) -> 0.18185535 | L14: =IFERROR(M14/J14,0%) -> -0.019469413 | M14: =K14-J14 -> -0.0036109195 | N14: =B14/$B$21 -> 0.022402921 | O14: =C14/$C$21 -> 0.025314577 | P14: =IFERROR(Q14/N14,0%) -> 0.1299677 | Q14: =IFERROR(O14-N14,0) -> 0.002911656
A15: Salud y Hospitalización | B15: ='Primas Diciembre 2024'!D15/1000 -> 3246.0557 | C15: ='Primas Diciembre 2025'!B15/1000 -> 3528.053 | D15: =IFERROR(E15/B15,0%) -> 0.086873818 | E15: =IFERROR(C15-B15,0) -> 281.99725 | F15: ='Siniestros Diciembre 2024'!E15/1000 -> 2443.8482 | G15: ='Siniestros Diciembre 2025'!B15/1000 -> 2666.7692 | H15: =IFERROR(I15/F15,0%) -> 0.091217207 | I15: =IFERROR(G15-F15,0) -> 222.92101 | J15: =IFERROR((F15/B15),0%) -> 0.75286699 | K15: =IFERROR(G15/C15,0%) -> 0.75587562 | L15: =IFERROR(M15/J15,0%) -> 0.0039962221 | M15: =K15-J15 -> 0.0030086237 | N15: =B15/$B$21 -> 0.17601679 | O15: =C15/$C$21 -> 0.17481415 | P15: =IFERROR(Q15/N15,0%) -> -0.0068325183 | Q15: =IFERROR(O15-N15,0) -> -0.0012026379
A16: Seguros Generales | B16: ='Primas Diciembre 2024'!D57/1000 -> 6413.4995 | C16: ='Primas Diciembre 2025'!B57/1000 -> 7125.184 | D16: =IFERROR(E16/B16,0%) -> 0.11096665 | E16: =IFERROR(C16-B16,0) -> 711.68453 | F16: ='Siniestros Diciembre 2024'!E57/1000 -> 2688.53 | G16: ='Siniestros Diciembre 2025'!B57/1000 -> 3568.6455 | H16: =IFERROR(I16/F16,0%) -> 0.32735937 | I16: =IFERROR(G16-F16,0) -> 880.11549 | J16: =IFERROR((F16/B16),0%) -> 0.4191986 | K16: =IFERROR(G16/C16,0%) -> 0.50084959 | L16: =IFERROR(M16/J16,0%) -> 0.19477878 | M16: =K16-J16 -> 0.081650991 | N16: =B16/$B$21 -> 0.34777086 | O16: =C16/$C$21 -> 0.35305111 | P16: =IFERROR(Q16/N16,0%) -> 0.015183113 | Q16: =IFERROR(O16-N16,0) -> 0.0052802445
A17: Incendio y Líneas Aliadas | B17: ='Primas Diciembre 2024'!D58/1000 -> 3597.3025 | C17: ='Primas Diciembre 2025'!B58/1000 -> 3994.6503 | D17: =IFERROR(E17/B17,0%) -> 0.11045717 | E17: =IFERROR(C17-B17,0) -> 397.34786 | F17: ='Siniestros Diciembre 2024'!E58/1000 -> 1028.7882 | G17: ='Siniestros Diciembre 2025'!B58/1000 -> 1697.7849 | H17: =IFERROR(I17/F17,0%) -> 0.65027641 | I17: =IFERROR(G17-F17,0) -> 668.99669 | J17: =IFERROR((F17/B17),0%) -> 0.28598879 | K17: =IFERROR(G17/C17,0%) -> 0.42501464 | L17: =IFERROR(M17/J17,0%) -> 0.48612342 | M17: =K17-J17 -> 0.13902585 | N17: =B17/$B$21 -> 0.19506308 | O17: =C17/$C$21 -> 0.19793394 | P17: =IFERROR(Q17/N17,0%) -> 0.014717566 | Q17: =IFERROR(O17-N17,0) -> 0.0028708537
A18: Vehículos Automotores | B18: ='Primas Diciembre 2024'!D59/1000 -> 2816.197 | C18: ='Primas Diciembre 2025'!B59/1000 -> 3130.5337 | D18: =IFERROR(E18/B18,0%) -> 0.11161743 | E18: =IFERROR(C18-B18,0) -> 314.33667 | F18: ='Siniestros Diciembre 2024'!E59/1000 -> 1659.7411 | G18: ='Siniestros Diciembre 2025'!B59/1000 -> 1870.8606 | H18: =IFERROR(I18/F18,0%) -> 0.12720026 | I18: =IFERROR(G18-F18,0) -> 211.1195 | J18: =IFERROR((F18/B18),0%) -> 0.58935547 | K18: =IFERROR(G18/C18,0%) -> 0.59761715 | L18: =IFERROR(M18/J18,0%) -> 0.014018162 | M18: =K18-J18 -> 0.0082616802 | N18: =B18/$B$21 -> 0.15270778 | O18: =C18/$C$21 -> 0.15511717 | P18: =IFERROR(Q18/N18,0%) -> 0.015777786 | Q18: =IFERROR(O18-N18,0) -> 0.0024093908
A19: Otros Seguros Generales | B19: ='Primas Diciembre 2024'!D22/1000 -> 1619.8638 | C19: ='Primas Diciembre 2025'!B22/1000 -> 1811.7784 | D19: =IFERROR(E19/B19,0%) -> 0.1184758 | E19: =IFERROR(C19-B19,0) -> 191.91465 | F19: ='Siniestros Diciembre 2024'!E22/1000 -> 557.16199 | G19: ='Siniestros Diciembre 2025'!B22/1000 -> 422.17715 | H19: =IFERROR(I19/F19,0%) -> -0.24227216 | I19: =IFERROR(G19-F19,0) -> -134.98484 | J19: =IFERROR((F19/B19),0%) -> 0.34395608 | K19: =IFERROR(G19/C19,0%) -> 0.23301809 | L19: =IFERROR(M19/J19,0%) -> -0.32253533 | M19: =K19-J19 -> -0.11093799 | N19: =B19/$B$21 -> 0.087836824 | O19: =C19/$C$21 -> 0.089773174 | P19: =IFERROR(Q19/N19,0%) -> 0.022044853 | Q19: =IFERROR(O19-N19,0) -> 0.0019363498
A20: Fianzas | B20: ='Primas Diciembre 2024'!D17/1000 -> 232.65236 | C20: ='Primas Diciembre 2025'!B17/1000 -> 293.7975 | D20: =IFERROR(E20/B20,0%) -> 0.26281764 | E20: =IFERROR(C20-B20,0) -> 61.145145 | F20: ='Siniestros Diciembre 2024'!E17/1000 -> 10.491704 | G20: ='Siniestros Diciembre 2025'!B17/1000 -> 41.792077 | H20: =IFERROR(I20/F20,0%) -> 2.9833449 | I20: =IFERROR(G20-F20,0) -> 31.300373 | J20: =IFERROR((F20/B20),0%) -> 0.045096058 | K20: =IFERROR(G20/C20,0%) -> 0.1422479 | L20: =IFERROR(M20/J20,0%) -> 2.1543311 | M20: =K20-J20 -> 0.097151839 | N20: =B20/$B$21 -> 0.012615533 | O20: =C20/$C$21 -> 0.014557594 | P20: =IFERROR(Q20/N20,0%) -> 0.15394207 | Q20: =IFERROR(O20-N20,0) -> 0.0019420611
A21: Totales | B21: ='Primas Diciembre 2024'!D61/1000 -> 18441.739 | C21: ='Primas Diciembre 2025'!B61/1000 -> 20181.735 | D21: =C21/B21-1 -> 0.094350991 | E21: =C21-B21 -> 1739.9963 | F21: ='Siniestros Diciembre 2024'!E61/1000 -> 7577.4097 | G21: ='Siniestros Diciembre 2025'!B61/1000 -> 8807.9031 | H21: =G21/F21-1 -> 0.16238971 | I21: =+G21-F21 -> 1230.4934 | J21: =IFERROR((F21/B21),0%) -> 0.41088369 | K21: =IFERROR(G21/C21,0%) -> 0.43642942 | L21: =IFERROR(M21/J21,0%) -> 0.062172668 | M21: =K21-J21 -> 0.025545735 | N21: =B21/$B$21 -> 1 | O21: =C21/$C$21 -> 1 | P21: =IFERROR(Q21/N21,0%) -> 0 | Q21: =IFERROR(O21-N21,0) -> 0
A22: En millones de USD | B22: =B21/B27 -> 742.73825 | C22: =C21/C27 -> 776.23253 | D22: =C22/B22-1 -> 0.04509567 | E22: =C22-B22 -> 33.494279 | F22: =F21/B27 -> 305.17903 | G22: =G21/C27 -> 338.77071 | H22: =G22/F22-1 -> 0.11007206 | I22: =+G22-F22 -> 33.591683
A24: Inflación Interanual Diciembre 2025 | D24: 0.0498 | F24: Inflación Acumulada Diciembre 2025 | J24: 0.0498
A25: Crecimiento Real | D25: =D21-D24 -> 0.044550991
A27: Tasa de Cambio (compra, promedio cierre mensual) | B27: 24.829392 | C27: 25.9996
A29: 1. Ramos Totales (USD)
A31: Rubro | B31: PRIMAS | F31: SINIESTROS
B32: 45657 | C32: 46022 | D32: Relativa | E32: Absoluta | F32: =B32 -> 45657 | G32: =C32 -> 46022 | H32: Relativa | I32: Absoluta
A33: Vida | B33: =B10/$B$27 -> 262.1001 | C33: =C10/$C$27 -> 265.42596 | D33: =IFERROR(E33/B33,0%) -> 0.012689297 | E33: =IFERROR(C33-B33,0) -> 3.325866 | F33: =F10/$B$27 -> 72.387275 | G33: =G10/$C$27 -> 77.325191 | H33: =IFERROR(I33/F33,0%) -> 0.068215249 | I33: =IFERROR(G33-F33,0) -> 4.937916
A34: Vida Individual | B34: =B11/$B$27 -> 36.424937 | C34: =C11/$C$27 -> 36.828408 | D34: =IFERROR(E34/B34,0%) -> 0.011076778 | E34: =IFERROR(C34-B34,0) -> 0.40347095 | F34: =F11/$B$27 -> 7.9189694 | G34: =G11/$C$27 -> 10.475255 | H34: =IFERROR(I34/F34,0%) -> 0.32280539 | I34: =IFERROR(G34-F34,0) -> 2.556286
A35: Vida Colectivo | B35: =B12/$B$27 -> 225.12099 | C35: =C12/$C$27 -> 228.07119 | D35: =IFERROR(E35/B35,0%) -> 0.013104965 | E35: =IFERROR(C35-B35,0) -> 2.9502026 | F35: =F12/$B$27 -> 64.064721 | G35: =G12/$C$27 -> 66.538623 | H35: =IFERROR(I35/F35,0%) -> 0.038615663 | I35: =IFERROR(G35-F35,0) -> 2.4739017
A36: Accidentes y Enfermedades | B36: =B13/$B$27 -> 147.72563 | C36: =C13/$C$27 -> 155.77188 | D36: =IFERROR(E36/B36,0%) -> 0.054467551 | E36: =IFERROR(C36-B36,0) -> 8.0462531 | F36: =F13/$B$27 -> 101.64947 | G36: =G13/$C$27 -> 106.32069 | H36: =IFERROR(I36/F36,0%) -> 0.045954126 | I36: =IFERROR(G36-F36,0) -> 4.6712126
A37: Accidentes Personales | B37: =B14/$B$27 -> 16.639506 | C37: =C14/$C$27 -> 19.649998 | D37: =IFERROR(E37/B37,0%) -> 0.18092435 | E37: =IFERROR(C37-B37,0) -> 3.0104918 | F37: =F14/$B$27 -> 3.0860672 | G37: =G14/$C$27 -> 3.5734573 | H37: =IFERROR(I37/F37,0%) -> 0.15793244 | I37: =IFERROR(G37-F37,0) -> 0.48739013
A38: Salud y Hospitalización | B38: =B15/$B$27 -> 130.7344 | C38: =C15/$C$27 -> 135.69643 | D38: =IFERROR(E38/B38,0%) -> 0.037955035 | E38: =IFERROR(C38-B38,0) -> 4.9620288 | F38: =F15/$B$27 -> 98.425617 | G38: =G15/$C$27 -> 102.56962 | H38: =IFERROR(I38/F38,0%) -> 0.042102933 | I38: =IFERROR(G38-F38,0) -> 4.1440072
A39: Seguros Generales | B39: =B16/$B$27 -> 258.30272 | C39: =C16/$C$27 -> 274.04976 | D39: =IFERROR(E39/B39,0%) -> 0.060963476 | E39: =IFERROR(C39-B39,0) -> 15.747032 | F39: =F16/$B$27 -> 108.28014 | G39: =G16/$C$27 -> 137.25771 | H39: =IFERROR(I39/F39,0%) -> 0.26761664 | I39: =IFERROR(G39-F39,0) -> 28.977568
A40: Incendio y Líneas Aliadas | B40: =B17/$B$27 -> 144.88081 | C40: =C17/$C$27 -> 153.64276 | D40: =IFERROR(E40/B40,0%) -> 0.060476934 | E40: =IFERROR(C40-B40,0) -> 8.7619474 | F40: =F17/$B$27 -> 41.434289 | G40: =G17/$C$27 -> 65.300423 | H40: =IFERROR(I40/F40,0%) -> 0.57599961 | I40: =IFERROR(G40-F40,0) -> 23.866134
A41: Vehículos Automotores | B41: =B18/$B$27 -> 113.42191 | C41: =C18/$C$27 -> 120.40699 | D41: =IFERROR(E41/B41,0%) -> 0.061584966 | E41: =IFERROR(C41-B41,0) -> 6.9850845 | F41: =F18/$B$27 -> 66.845823 | G41: =G18/$C$27 -> 71.957285 | H41: =IFERROR(I41/F41,0%) -> 0.076466436 | I41: =IFERROR(G41-F41,0) -> 5.1114619
A42: Otros Seguros Generales | B42: =B19/$B$27 -> 65.239769 | C42: =C19/$C$27 -> 69.684858 | D42: =IFERROR(E42/B42,0%) -> 0.06813465 | E42: =IFERROR(C42-B42,0) -> 4.4450888 | F42: =F19/$B$27 -> 22.439615 | G42: =G19/$C$27 -> 16.237833 | H42: =IFERROR(I42/F42,0%) -> -0.27637651 | I42: =IFERROR(G42-F42,0) -> -6.2017826
A43: Fianzas | B43: =B20/$B$27 -> 9.3700386 | C43: =C20/$C$27 -> 11.300078 | D43: =IFERROR(E43/B43,0%) -> 0.20597986 | E43: =IFERROR(C43-B43,0) -> 1.9300392 | F43: =F20/$B$27 -> 0.4225518 | G43: =G20/$C$27 -> 1.6074123 | H43: =IFERROR(I43/F43,0%) -> 2.8040597 | I43: =IFERROR(G43-F43,0) -> 1.1848605
A44: Totales | B44: =B21/B27 -> 742.73825 | C44: =C21/C27 -> 776.23253 | D44: =C44/B44-1 -> 0.04509567 | E44: =C44-B44 -> 33.494279 | F44: =F21/B27 -> 305.17903 | G44: =G21/C27 -> 338.77071 | H44: =G44/F44-1 -> 0.11007206 | I44: =+G44-F44 -> 33.591683

Sheet 2. Vida
A1: Sector Asegurador Hondureño
A2: Situación de Primas y Siniestros por Ramo
A3: ='1. Ramos Totales'!A3 -> Al 31 de diciembre de 2025
A4: (Valores en millones de Lempiras y Porcentajes)
A6: 2. Vida
A8: No. | B8: Compañía | C8: Primas | G8: Siniestros | K8: Siniestros/Primas | O8: Participación de mercado
C9: ='1. Ramos Totales'!$B$9 -> 45657 | D9: ='1. Ramos Totales'!$C$9 -> 46022 | E9: Relativa | F9: Absoluta | G9: ='1. Ramos Totales'!$B$9 -> 45657 | H9: ='1. Ramos Totales'!$C$9 -> 46022 | I9: Relativa | J9: Absoluta | K9: ='1. Ramos Totales'!$B$9 -> 45657 | L9: ='1. Ramos Totales'!$C$9 -> 46022 | M9: Relativa | N9: Absoluta | O9: ='1. Ramos Totales'!$B$9 -> 45657 | P9: ='1. Ramos Totales'!$C$9 -> 46022 | Q9: Relativa | R9: Absoluta
A10: 1 | B10: ='Primas Diciembre 2024'!$I11 -> MAPFRE SEGUROS | C10: ='Primas Diciembre 2024'!I51/1000 -> 1431.9608 | D10: ='Primas Diciembre 2025'!E51/1000 -> 1465.588 | E10: =IFERROR(F10/C10,0%) -> 0.02348336 | F10: =IFERROR(D10-C10,0) -> 33.62725 | G10: ='Siniestros Diciembre 2024'!K51/1000 -> 323.77839 | H10: ='Siniestros Diciembre 2025'!H51/1000 -> 338.41864 | I10: =IFERROR(J10/G10,0%) -> 0.045216877 | J10: =IFERROR(H10-G10,0) -> 14.640248 | K10: =IFERROR((G10/C10),0%) -> 0.22610842 | L10: =IFERROR(H10/D10,0%) -> 0.2309098 | M10: =IFERROR(N10/K10,0%) -> 0.021234852 | N10: =L10-K10 -> 0.0048013788 | O10: =C10/$C$22 -> 0.22003809 | P10: =D10/$D$22 -> 0.21237424 | Q10: =IFERROR(R10/O10,0%) -> -0.034829635 | R10: =IFERROR(P10-O10,0) -> -0.0076638463
A11: 2 | B11: ='Primas Diciembre 2024'!$J11 -> FICOHSA SEGUROS | C11: ='Primas Diciembre 2024'!J51/1000 -> 1124.4967 | D11: ='Primas Diciembre 2025'!F51/1000 -> 1300.2513 | E11: =IFERROR(F11/C11,0%) -> 0.15629627 | F11: =IFERROR(D11-C11,0) -> 175.75463 | G11: ='Siniestros Diciembre 2024'!M51/1000 -> 332.94247 | H11: ='Siniestros Diciembre 2025'!J51/1000 -> 311.91989 | I11: =IFERROR(J11/G11,0%) -> -0.063141778 | J11: =IFERROR(H11-G11,0) -> -21.02258 | K11: =IFERROR((G11/C11),0%) -> 0.29608133 | L11: =IFERROR(H11/D11,0%) -> 0.239892 | M11: =IFERROR(N11/K11,0%) -> -0.18977666 | N11: =L11-K11 -> -0.056189326 | O11: =C11/$C$22 -> 0.17279251 | P11: =D11/$D$22 -> 0.18841576 | Q11: =IFERROR(R11/O11,0%) -> 0.090416251 | R11: =IFERROR(P11-O11,0) -> 0.015623251
A12: 3 | B12: ='Primas Diciembre 2024'!$L11 -> SEGUROS ATLÁNTIDA | C12: ='Primas Diciembre 2024'!L51/1000 -> 774.12862 | D12: ='Primas Diciembre 2025'!H51/1000 -> 770.53317 | E12: =IFERROR(F12/C12,0%) -> -0.0046445179 | F12: =IFERROR(D12-C12,0) -> -3.5954543 | G12: ='Siniestros Diciembre 2024'!Q51/1000 -> 240.98385 | H12: ='Siniestros Diciembre 2025'!N51/1000 -> 285.83678 | I12: =IFERROR(J12/G12,0%) -> 0.18612422 | J12: =IFERROR(H12-G12,0) -> 44.852931 | K12: =IFERROR((G12/C12),0%) -> 0.31129691 | L12: =IFERROR(H12/D12,0%) -> 0.37095973 | M12: =IFERROR(N12/K12,0%) -> 0.1916589 | N12: =L12-K12 -> 0.059662824 | O12: =C12/$C$22 -> 0.11895422 | P12: =D12/$D$22 -> 0.1116558 | Q12: =IFERROR(R12/O12,0%) -> -0.061354926 | R12: =IFERROR(P12-O12,0) -> -0.0072984276
A13: 4 | B13: ='Primas Diciembre 2024'!$G11 -> SEGUROS DAVIVIENDA | C13: ='Primas Diciembre 2024'!G51/1000 -> 727.74247 | D13: ='Primas Diciembre 2025'!C51/1000 -> 739.87358 | E13: =IFERROR(F13/C13,0%) -> 0.016669505 | F13: =IFERROR(D13-C13,0) -> 12.131107 | G13: ='Siniestros Diciembre 2024'!G51/1000 -> 152.22861 | H13: ='Siniestros Diciembre 2025'!D51/1000 -> 240.64329 | I13: =IFERROR(J13/G13,0%) -> 0.58080195 | J13: =IFERROR(H13-G13,0) -> 88.414676 | K13: =IFERROR((G13/C13),0%) -> 0.20917924 | L13: =IFERROR(H13/D13,0%) -> 0.3252492 | M13: =IFERROR(N13/K13,0%) -> 0.55488282 | N13: =L13-K13 -> 0.11606996 | O13: =C13/$C$22 -> 0.11182643 | P13: =D13/$D$22 -> 0.107213 | Q13: =IFERROR(R13/O13,0%) -> -0.04125527 | R13: =IFERROR(P13-O13,0) -> -0.0046134296
A14: 5 | B14: ='Primas Diciembre 2024'!$H11 -> PALIC | C14: ='Primas Diciembre 2024'!H51/1000 -> 708.21103 | D14: ='Primas Diciembre 2025'!D51/1000 -> 736.63882 | E14: =IFERROR(F14/C14,0%) -> 0.040140288 | F14: =IFERROR(D14-C14,0) -> 28.427795 | G14: ='Siniestros Diciembre 2024'!I51/1000 -> 109.1135 | H14: ='Siniestros Diciembre 2025'!F51/1000 -> 129.06297 | I14: =IFERROR(J14/G14,0%) -> 0.18283227 | J14: =IFERROR(H14-G14,0) -> 19.94947 | K14: =IFERROR((G14/C14),0%) -> 0.1540692 | L14: =IFERROR(H14/D14,0%) -> 0.17520523 | M14: =IFERROR(N14/K14,0%) -> 0.13718532 | N14: =L14-K14 -> 0.021136033 | O14: =C14/$C$22 -> 0.10882519 | P14: =D14/$D$22 -> 0.10674426 | Q14: =IFERROR(R14/O14,0%) -> -0.019121736 | R14: =IFERROR(P14-O14,0) -> -0.0020809265
A15: 6 | B15: ='Primas Diciembre 2024'!$M11 -> CREFISA | C15: ='Primas Diciembre 2024'!M51/1000 -> 368.06353 | D15: ='Primas Diciembre 2025'!I51/1000 -> 408.60058 | E15: =IFERROR(F15/C15,0%) -> 0.11013601 | F15: =IFERROR(D15-C15,0) -> 40.537049 | G15: ='Siniestros Diciembre 2024'!S51/1000 -> 115.52164 | H15: ='Siniestros Diciembre 2025'!P51/1000 -> 146.72312 | I15: =IFERROR(J15/G15,0%) -> 0.27009209 | J15: =IFERROR(H15-G15,0) -> 31.201481 | K15: =IFERROR((G15/C15),0%) -> 0.31386331 | L15: =IFERROR(H15/D15,0%) -> 0.35908691 | M15: =IFERROR(N15/K15,0%) -> 0.14408692 | N15: =L15-K15 -> 0.045223599 | O15: =C15/$C$22 -> 0.056557412 | P15: =D15/$D$22 -> 0.059209162 | Q15: =IFERROR(R15/O15,0%) -> 0.046885979 | R15: =IFERROR(P15-O15,0) -> 0.0026517496
A16: 7 | B16: ='Primas Diciembre 2024'!$N11 -> SEGUROS EQUIDAD | C16: ='Primas Diciembre 2024'!N51/1000 -> 492.61278 | D16: ='Primas Diciembre 2025'!J51/1000 -> 401.65467 | E16: =IFERROR(F16/C16,0%) -> -0.18464424 | F16: =IFERROR(D16-C16,0) -> -90.958115 | G16: ='Siniestros Diciembre 2024'!U51/1000 -> 243.98002 | H16: ='Siniestros Diciembre 2025'!R51/1000 -> 228.24947 | I16: =IFERROR(J16/G16,0%) -> -0.064474767 | J16: =IFERROR(H16-G16,0) -> -15.730555 | K16: =IFERROR((G16/C16),0%) -> 0.49527749 | L16: =IFERROR(H16/D16,0%) -> 0.56827291 | M16: =IFERROR(N16/K16,0%) -> 0.14738288 | N16: =L16-K16 -> 0.072995422 | O16: =C16/$C$22 -> 0.075695911 | P16: =D16/$D$22 -> 0.058202649 | Q16: =IFERROR(R16/O16,0%) -> -0.23109916 | R16: =IFERROR(P16-O16,0) -> -0.017493262
A17: 8 | B17: ='Primas Diciembre 2024'!$O11 -> SEGUROS DEL PAÍS | C17: ='Primas Diciembre 2024'!O51/1000 -> 293.76795 | D17: ='Primas Diciembre 2025'!K51/1000 -> 321.79939 | E17: =IFERROR(F17/C17,0%) -> 0.095420336 | F17: =IFERROR(D17-C17,0) -> 28.031437 | G17: ='Siniestros Diciembre 2024'!W51/1000 -> 58.031663 | H17: ='Siniestros Diciembre 2025'!T51/1000 -> 79.050757 | I17: =IFERROR(J17/G17,0%) -> 0.36220043 | J17: =IFERROR(H17-G17,0) -> 21.019093 | K17: =IFERROR((G17/C17),0%) -> 0.19754252 | L17: =IFERROR(H17/D17,0%) -> 0.24565229 | M17: =IFERROR(N17/K17,0%) -> 0.2435413 | N17: =L17-K17 -> 0.048109764 | O17: =C17/$C$22 -> 0.045140998 | P17: =D17/$D$22 -> 0.046631045 | Q17: =IFERROR(R17/O17,0%) -> 0.03300873 | R17: =IFERROR(P17-O17,0) -> 0.001490047
A18: 9 | B18: ='Primas Diciembre 2024'!$Q11 -> ASEGURADORA RURAL | C18: ='Primas Diciembre 2024'!Q51/1000 -> 285.62994 | D18: ='Primas Diciembre 2025'!M51/1000 -> 316.46013 | E18: =IFERROR(F18/C18,0%) -> 0.10793753 | F18: =IFERROR(D18-C18,0) -> 30.830191 | G18: ='Siniestros Diciembre 2024'!AA51/1000 -> 133.92161 | H18: ='Siniestros Diciembre 2025'!X51/1000 -> 128.56251 | I18: =IFERROR(J18/G18,0%) -> -0.040016657 | J18: =IFERROR(H18-G18,0) -> -5.3590951 | K18: =IFERROR((G18/C18),0%) -> 0.46886404 | L18: =IFERROR(H18/D18,0%) -> 0.40625185 | M18: =IFERROR(N18/K18,0%) -> -0.13354019 | N18: =L18-K18 -> -0.062612194 | O18: =C18/$C$22 -> 0.043890494 | P18: =D18/$D$22 -> 0.045857348 | Q18: =IFERROR(R18/O18,0%) -> 0.04481276 | R18: =IFERROR(P18-O18,0) -> 0.0019668542
A19: 10 | B19: ='Primas Diciembre 2024'!$P11 -> SEGUROS LAFISE | C19: ='Primas Diciembre 2024'!P51/1000 -> 200.55151 | D19: ='Primas Diciembre 2025'!L51/1000 -> 192.84464 | E19: =IFERROR(F19/C19,0%) -> -0.038428378 | F19: =IFERROR(D19-C19,0) -> -7.7068692 | G19: ='Siniestros Diciembre 2024'!Y51/1000 -> 53.214254 | H19: ='Siniestros Diciembre 2025'!V51/1000 -> 68.584484 | I19: =IFERROR(J19/G19,0%) -> 0.2888367 | J19: =IFERROR(H19-G19,0) -> 15.37023 | K19: =IFERROR((G19/C19),0%) -> 0.26533959 | L19: =IFERROR(H19/D19,0%) -> 0.35564631 | M19: =IFERROR(N19/K19,0%) -> 0.34034394 | N19: =L19-K19 -> 0.090306721 | O19: =C19/$C$22 -> 0.030817164 | P19: =D19/$D$22 -> 0.027944575 | Q19: =IFERROR(R19/O19,0%) -> -0.09321395 | R19: =IFERROR(P19-O19,0) -> -0.0028725896
A20: 11 | B20: ='Primas Diciembre 2024'!$R11 -> ASSA CIA. DE SEGUROS | C20: ='Primas Diciembre 2024'!R51/1000 -> 18.600111 | D20: ='Primas Diciembre 2025'!N51/1000 -> 157.07301 | E20: =IFERROR(F20/C20,0%) -> 7.4447352 | F20: =IFERROR(D20-C20,0) -> 138.4729 | G20: ='Siniestros Diciembre 2024'!AC51/1000 -> 7.8655091 | H20: ='Siniestros Diciembre 2025'!Z51/1000 -> 25.169193 | I20: =IFERROR(J20/G20,0%) -> 2.1999445 | J20: =IFERROR(H20-G20,0) -> 17.303684 | K20: =IFERROR((G20/C20),0%) -> 0.42287431 | L20: =IFERROR(H20/D20,0%) -> 0.16023881 | M20: =IFERROR(N20/K20,0%) -> -0.62107225 | N20: =L20-K20 -> -0.2626355 | O20: =C20/$C$22 -> 0.002858132 | P20: =D20/$D$22 -> 0.022761009 | Q20: =IFERROR(R20/O20,0%) -> 6.9635962 | R20: =IFERROR(P20-O20,0) -> 0.019902877
A21: 12 | B21: ='Primas Diciembre 2024'!$K11 -> SEGUROS CONTINENTAL | C21: ='Primas Diciembre 2024'!K51/1000 -> 82.02052 | D21: ='Primas Diciembre 2025'!G51/1000 -> 89.6515 | E21: =IFERROR(F21/C21,0%) -> 0.093037451 | F21: =IFERROR(D21-C21,0) -> 7.6309801 | G21: ='Siniestros Diciembre 2024'!O51/1000 -> 25.750475 | H21: ='Siniestros Diciembre 2025'!L51/1000 -> 28.202925 | I21: =IFERROR(J21/G21,0%) -> 0.095239011 | J21: =IFERROR(H21-G21,0) -> 2.4524498 | K21: =IFERROR((G21/C21),0%) -> 0.31395162 | L21: =IFERROR(H21/D21,0%) -> 0.31458397 | M21: =IFERROR(N21/K21,0%) -> 0.0020141671 | N21: =L21-K21 -> 0.00063235102 | O21: =C21/$C$22 -> 0.012603445 | P21: =D21/$D$22 -> 0.012991147 | Q21: =IFERROR(R21/O21,0%) -> 0.03076161 | R21: =IFERROR(P21-O21,0) -> 0.00038770225
A22: Total general | C22: =SUM(C10:C21) -> 6507.7859 | D22: =SUM(D10:D21) -> 6900.9688 | E22: =IFERROR(F22/C22,0%) -> 0.060417307 | F22: =D22-C22 -> 393.1829 | G22: =SUM(G10:G21) -> 1797.332 | H22: =SUM(H10:H21) -> 2010.424 | I22: =IFERROR(J22/G22,0%) -> 0.1185602 | J22: =H22-G22 -> 213.09203 | K22: =IFERROR((G22/C22),0%) -> 0.27618179 | L22: =IFERROR(H22/D22,0%) -> 0.2913249 | M22: =IFERROR(N22/K22,0%) -> 0.054830195 | N22: =L22-K22 -> 0.015143102
A24: ='1. Ramos Totales'!A$24 -> Inflación Interanual Diciembre 2025 | E24: ='1. Ramos Totales'!$D$24 -> 0.0498 | G24: ='1. Ramos Totales'!$F$24 -> Inflación Acumulada Diciembre 2025 | J24: ='1. Ramos Totales'!$J$24 -> 0.0498
A25: Crecimiento Real | E25: =E22-E24 -> 0.010617307

Sheet 2.1 Vida Individual
A1: Sector Asegurador Hondureño
A2: Situación de Primas y Siniestros por Ramo
A3: ='1. Ramos Totales'!A3 -> Al 31 de diciembre de 2025
A4: (Valores en millones de Lempiras y Porcentajes)
A6: 2. 1 Vida Individual
A8: No. | B8: Compañía | C8: Primas | G8: Siniestros | K8: Siniestros/Primas | O8: Participación de mercado
C9: ='1. Ramos Totales'!$B$9 -> 45657 | D9: ='1. Ramos Totales'!$C$9 -> 46022 | E9: Relativa | F9: Absoluta | G9: ='1. Ramos Totales'!$B$9 -> 45657 | H9: ='1. Ramos Totales'!$C$9 -> 46022 | I9: Relativa | J9: Absoluta | K9: ='1. Ramos Totales'!$B$9 -> 45657 | L9: ='1. Ramos Totales'!$C$9 -> 46022 | M9: Relativa | N9: Absoluta | O9: ='1. Ramos Totales'!$B$9 -> 45657 | P9: ='1. Ramos Totales'!$C$9 -> 46022 | Q9: Relativa | R9: Absoluta
A10: 1 | B10: ='Primas Diciembre 2024'!$H11 -> PALIC | C10: ='Primas Diciembre 2024'!H55/1000 -> 338.91513 | D10: ='Primas Diciembre 2025'!D55/1000 -> 379.40606 | E10: =IFERROR(F10/C10,0%) -> 0.11947219 | F10: =IFERROR(D10-C10,0) -> 40.490934 | G10: ='Siniestros Diciembre 2024'!I55/1000 -> 71.618304 | H10: ='Siniestros Diciembre 2025'!F55/1000 -> 85.010821 | I10: =IFERROR(J10/G10,0%) -> 0.18699852 | J10: =IFERROR(H10-G10,0) -> 13.392517 | K10: =IFERROR((G10/C10),0%) -> 0.21131634 | L10: =IFERROR(H10/D10,0%) -> 0.22406289 | M10: =IFERROR(N10/K10,0%) -> 0.060319789 | N10: =L10-K10 -> 0.012746557 | O10: =C10/$C$22 -> 0.37473657 | P10: =D10/$D$22 -> 0.39623667 | Q10: =IFERROR(R10/O10,0%) -> 0.057373902 | R10: =IFERROR(P10-O10,0) -> 0.021500099
A11: 2 | B11: ='Primas Diciembre 2024'!$G11 -> SEGUROS DAVIVIENDA | C11: ='Primas Diciembre 2024'!G55/1000 -> 312.35542 | D11: ='Primas Diciembre 2025'!C55/1000 -> 311.5464 | E11: =IFERROR(F11/C11,0%) -> -0.0025900772 | F11: =IFERROR(D11-C11,0) -> -0.80902465 | G11: ='Siniestros Diciembre 2024'!G55/1000 -> 69.06604 | H11: ='Siniestros Diciembre 2025'!D55/1000 -> 116.46894 | I11: =IFERROR(J11/G11,0%) -> 0.68634171 | J11: =IFERROR(H11-G11,0) -> 47.402904 | K11: =IFERROR((G11/C11),0%) -> 0.22111363 | L11: =IFERROR(H11/D11,0%) -> 0.37384141 | M11: =IFERROR(N11/K11,0%) -> 0.69072081 | N11: =L11-K11 -> 0.15272778 | O11: =C11/$C$22 -> 0.34536965 | P11: =D11/$D$22 -> 0.32536672 | Q11: =IFERROR(R11/O11,0%) -> -0.057917446 | R11: =IFERROR(P11-O11,0) -> -0.020002928
A12: 3 | B12: ='Primas Diciembre 2024'!$J11 -> FICOHSA SEGUROS | C12: ='Primas Diciembre 2024'!J55/1000 -> 92.220254 | D12: ='Primas Diciembre 2025'!F55/1000 -> 97.773838 | E12: =IFERROR(F12/C12,0%) -> 0.060220875 | F12: =IFERROR(D12-C12,0) -> 5.5535844 | G12: ='Siniestros Diciembre 2024'!M55/1000 -> 24.117753 | H12: ='Siniestros Diciembre 2025'!J55/1000 -> 23.054899 | I12: =IFERROR(J12/G12,0%) -> -0.044069375 | J12: =IFERROR(H12-G12,0) -> -1.0628543 | K12: =IFERROR((G12/C12),0%) -> 0.26152339 | L12: =IFERROR(H12/D12,0%) -> 0.23579824 | M12: =IFERROR(N12/K12,0%) -> -0.098366531 | N12: =L12-K12 -> -0.025725149 | O12: =C12/$C$22 -> 0.10196742 | P12: =D12/$D$22 -> 0.10211112 | Q12: =IFERROR(R12/O12,0%) -> 0.0014093172 | R12: =IFERROR(P12-O12,0) -> 0.00014370443
A13: 4 | B13: ='Primas Diciembre 2024'!$K11 -> SEGUROS CONTINENTAL | C13: ='Primas Diciembre 2024'!K55/1000 -> 58.814421 | D13: ='Primas Diciembre 2025'!G55/1000 -> 67.27082 | E13: =IFERROR(F13/C13,0%) -> 0.14378106 | F13: =IFERROR(D13-C13,0) -> 8.4563996 | G13: ='Siniestros Diciembre 2024'!O55/1000 -> 8.396654 | H13: ='Siniestros Diciembre 2025'!L55/1000 -> 19.961438 | I13: =IFERROR(J13/G13,0%) -> 1.3773086 | J13: =IFERROR(H13-G13,0) -> 11.564784 | K13: =IFERROR((G13/C13),0%) -> 0.14276522 | L13: =IFERROR(H13/D13,0%) -> 0.29673249 | M13: =IFERROR(N13/K13,0%) -> 1.0784647 | N13: =L13-K13 -> 0.15396726 | O13: =C13/$C$22 -> 0.065030776 | P13: =D13/$D$22 -> 0.07025498 | Q13: =IFERROR(R13/O13,0%) -> 0.080334329 | R13: =IFERROR(P13-O13,0) -> 0.0052242038
A14: 5 | B14: ='Primas Diciembre 2024'!$I11 -> MAPFRE SEGUROS | C14: ='Primas Diciembre 2024'!I55/1000 -> 43.653249 | D14: ='Primas Diciembre 2025'!E55/1000 -> 41.58141 | E14: =IFERROR(F14/C14,0%) -> -0.047461291 | F14: =IFERROR(D14-C14,0) -> -2.0718396 | G14: ='Siniestros Diciembre 2024'!K55/1000 -> 10.273022 | H14: ='Siniestros Diciembre 2025'!H55/1000 -> 16.26929 | I14: =IFERROR(J14/G14,0%) -> 0.58369073 | J14: =IFERROR(H14-G14,0) -> 5.9962679 | K14: =IFERROR((G14/C14),0%) -> 0.23533236 | L14: =IFERROR(H14/D14,0%) -> 0.39126356 | M14: =IFERROR(N14/K14,0%) -> 0.66259987 | N14: =L14-K14 -> 0.15593119 | O14: =C14/$C$22 -> 0.048267154 | P14: =D14/$D$22 -> 0.043425977 | Q14: =IFERROR(R14/O14,0%) -> -0.10029961 | R14: =IFERROR(P14-O14,0) -> -0.0048411765
A15: 6 | B15: ='Primas Diciembre 2024'!$O11 -> SEGUROS DEL PAÍS | C15: ='Primas Diciembre 2024'!O55/1000 -> 19.450308 | D15: ='Primas Diciembre 2025'!K55/1000 -> 20.063308 | E15: =IFERROR(F15/C15,0%) -> 0.031516242 | F15: =IFERROR(D15-C15,0) -> 0.61300059 | G15: ='Siniestros Diciembre 2024'!W55/1000 -> 5.7660791 | H15: ='Siniestros Diciembre 2025'!T55/1000 -> 6.4556599 | I15: =IFERROR(J15/G15,0%) -> 0.11959267 | J15: =IFERROR(H15-G15,0) -> 0.68958079 | K15: =IFERROR((G15/C15),0%) -> 0.29645182 | L15: =IFERROR(H15/D15,0%) -> 0.32176448 | M15: =IFERROR(N15/K15,0%) -> 0.0853854 | N15: =L15-K15 -> 0.025312658 | O15: =C15/$C$22 -> 0.021506096 | P15: =D15/$D$22 -> 0.020953324 | Q15: =IFERROR(R15/O15,0%) -> -0.025703041 | R15: =IFERROR(P15-O15,0) -> -0.00055277207
A16: 7 | B16: ='Primas Diciembre 2024'!$L11 -> SEGUROS ATLÁNTIDA | C16: ='Primas Diciembre 2024'!L55/1000 -> 16.370249 | D16: ='Primas Diciembre 2025'!H55/1000 -> 17.343844 | E16: =IFERROR(F16/C16,0%) -> 0.05947344 | F16: =IFERROR(D16-C16,0) -> 0.97359505 | G16: ='Siniestros Diciembre 2024'!Q55/1000 -> 6.78534 | H16: ='Siniestros Diciembre 2025'!N55/1000 -> 2.6063985 | I16: =IFERROR(J16/G16,0%) -> -0.61587798 | J16: =IFERROR(H16-G16,0) -> -4.1789415 | K16: =IFERROR((G16/C16),0%) -> 0.41449216 | L16: =IFERROR(H16/D16,0%) -> 0.15027801 | M16: =IFERROR(N16/K16,0%) -> -0.63744063 | N16: =L16-K16 -> -0.26421414 | O16: =C16/$C$22 -> 0.018100493 | P16: =D16/$D$22 -> 0.018113224 | Q16: =IFERROR(R16/O16,0%) -> 0.00070334339 | R16: =IFERROR(P16-O16,0) -> 1.2730862e-05
A17: 8 | B17: ='Primas Diciembre 2024'!$P11 -> SEGUROS LAFISE | C17: ='Primas Diciembre 2024'!P55/1000 -> 17.873668 | D17: ='Primas Diciembre 2025'!L55/1000 -> 17.279997 | E17: =IFERROR(F17/C17,0%) -> -0.033214831 | F17: =IFERROR(D17-C17,0) -> -0.59367086 | G17: ='Siniestros Diciembre 2024'!Y55/1000 -> 0.6 | H17: ='Siniestros Diciembre 2025'!V55/1000 -> 2.525 | I17: =IFERROR(J17/G17,0%) -> 3.2083333 | J17: =IFERROR(H17-G17,0) -> 1.925 | K17: =IFERROR((G17/C17),0%) -> 0.033568935 | L17: =IFERROR(H17/D17,0%) -> 0.14612271 | M17: =IFERROR(N17/K17,0%) -> 3.3529147 | N17: =L17-K17 -> 0.11255377 | O17: =C17/$C$22 -> 0.019762815 | P17: =D17/$D$22 -> 0.018046545 | Q17: =IFERROR(R17/O17,0%) -> -0.086843413 | R17: =IFERROR(P17-O17,0) -> -0.0017162703
A18: 9 | B18: ='Primas Diciembre 2024'!$M11 -> CREFISA | C18: ='Primas Diciembre 2024'!M55/1000 -> 3.1895241 | D18: ='Primas Diciembre 2025'!I55/1000 -> 3.0334318 | E18: =IFERROR(F18/C18,0%) -> -0.048939029 | F18: =IFERROR(D18-C18,0) -> -0.15609221 | G18: ='Siniestros Diciembre 2024'!S55/1000 -> 0 | H18: ='Siniestros Diciembre 2025'!P55/1000 -> 0 | I18: =IFERROR(J18/G18,0%) -> 0 | J18: =IFERROR(H18-G18,0) -> 0 | K18: =IFERROR((G18/C18),0%) -> 0 | L18: =IFERROR(H18/D18,0%) -> 0 | M18: =IFERROR(N18/K18,0%) -> 0 | N18: =L18-K18 -> 0 | O18: =C18/$C$22 -> 0.0035266389 | P18: =D18/$D$22 -> 0.0031679961 | Q18: =IFERROR(R18/O18,0%) -> -0.10169537 | R18: =IFERROR(P18-O18,0) -> -0.00035864286
A19: 10 | B19: ='Primas Diciembre 2024'!$Q11 -> ASEGURADORA RURAL | C19: ='Primas Diciembre 2024'!Q55/1000 -> 1.566793 | D19: ='Primas Diciembre 2025'!M55/1000 -> 2.2247548 | E19: =IFERROR(F19/C19,0%) -> 0.41994176 | F19: =IFERROR(D19-C19,0) -> 0.6579618 | G19: ='Siniestros Diciembre 2024'!AA55/1000 -> 0 | H19: ='Siniestros Diciembre 2025'!X55/1000 -> 0 | I19: =IFERROR(J19/G19,0%) -> 0 | J19: =IFERROR(H19-G19,0) -> 0 | K19: =IFERROR((G19/C19),0%) -> 0 | L19: =IFERROR(H19/D19,0%) -> 0 | M19: =IFERROR(N19/K19,0%) -> 0 | N19: =L19-K19 -> 0 | O19: =C19/$C$22 -> 0.0017323942 | P19: =D19/$D$22 -> 0.0023234458 | Q19: =IFERROR(R19/O19,0%) -> 0.34117611 | R19: =IFERROR(P19-O19,0) -> 0.00059105153
A20: 11 | B20: ='Primas Diciembre 2024'!$N11 -> SEGUROS EQUIDAD | C20: ='Primas Diciembre 2024'!N55/1000 -> 0 | D20: ='Primas Diciembre 2025'!J55/1000 -> 0 | E20: =IFERROR(F20/C20,0%) -> 0 | F20: =IFERROR(D20-C20,0) -> 0 | G20: ='Siniestros Diciembre 2024'!U55/1000 -> 0 | H20: ='Siniestros Diciembre 2025'!H80/1000 -> 0 | I20: =IFERROR(J20/G20,0%) -> 0 | J20: =IFERROR(H20-G20,0) -> 0 | K20: =IFERROR((G20/C20),0%) -> 0 | L20: =IFERROR(H20/D20,0%) -> 0 | M20: =IFERROR(N20/K20,0%) -> 0 | N20: =L20-K20 -> 0 | O20: =C20/$C$22 -> 0 | P20: =D20/$D$22 -> 0 | Q20: =IFERROR(R20/O20,0%) -> 0 | R20: =IFERROR(P20-O20,0) -> 0
A21: 12 | B21: ='Primas Diciembre 2024'!$R11 -> ASSA CIA. DE SEGUROS | C21: ='Primas Diciembre 2024'!R55/1000 -> 0 | D21: ='Primas Diciembre 2025'!N55/1000 -> 0 | E21: =IFERROR(F21/C21,0%) -> 0 | F21: =IFERROR(D21-C21,0) -> 0 | G21: ='Siniestros Diciembre 2024'!AC55/1000 -> 0 | H21: ='Siniestros Diciembre 2025'!Z55/1000 -> 0 | I21: =IFERROR(J21/G21,0%) -> 0 | J21: =IFERROR(H21-G21,0) -> 0 | K21: =IFERROR((G21/C21),0%) -> 0 | L21: =IFERROR(H21/D21,0%) -> 0 | M21: =IFERROR(N21/K21,0%) -> 0 | N21: =L21-K21 -> 0 | O21: =C21/$C$22 -> 0 | P21: =D21/$D$22 -> 0 | Q21: =IFERROR(R21/O21,0%) -> 0 | R21: =IFERROR(P21-O21,0) -> 0
A22: Total general | C22: =SUM(C10:C21) -> 904.40902 | D22: =SUM(D10:D21) -> 957.52387 | E22: =IFERROR(F22/C22,0%) -> 0.058728791 | F22: =D22-C22 -> 53.114848 | G22: =SUM(G10:G21) -> 196.62319 | H22: =SUM(H10:H21) -> 272.35245 | I22: =IFERROR(J22/G22,0%) -> 0.38514916 | J22: =H22-G22 -> 75.729258 | K22: =IFERROR((G22/C22),0%) -> 0.21740517 | L22: =IFERROR(H22/D22,0%) -> 0.28443411 | M22: =IFERROR(N22/K22,0%) -> 0.30831349 | N22: =L22-K22 -> 0.067028946
A24: ='1. Ramos Totales'!A$24 -> Inflación Interanual Diciembre 2025 | E24: ='1. Ramos Totales'!$D$24 -> 0.0498 | G24: ='1. Ramos Totales'!$F$24 -> Inflación Acumulada Diciembre 2025 | J24: ='1. Ramos Totales'!$J$24 -> 0.0498
A25: Crecimiento Real | E25: =E22-E24 -> 0.0089287906

Sheet 2.2 Vida Colectivo
A1: Sector Asegurador Hondureño
A2: Situación de Primas y Siniestros por Ramo
A3: ='1. Ramos Totales'!A3 -> Al 31 de diciembre de 2025
A4: (Valores en millones de Lempiras y Porcentajes)
A6: 2.2 Vida Colectivo
A8: No. | B8: Compañía | C8: Primas | G8: Siniestros | K8: Siniestros/Primas | O8: Participación de mercado
C9: ='1. Ramos Totales'!$B$9 -> 45657 | D9: ='1. Ramos Totales'!$C$9 -> 46022 | E9: Relativa | F9: Absoluta | G9: ='1. Ramos Totales'!$B$9 -> 45657 | H9: ='1. Ramos Totales'!$C$9 -> 46022 | I9: Relativa | J9: Absoluta | K9: ='1. Ramos Totales'!$B$9 -> 45657 | L9: ='1. Ramos Totales'!$C$9 -> 46022 | M9: Relativa | N9: Absoluta | O9: ='1. Ramos Totales'!$B$9 -> 45657 | P9: ='1. Ramos Totales'!$C$9 -> 46022 | Q9: Relativa | R9: Absoluta
A10: 1 | B10: ='Primas Diciembre 2024'!$I11 -> MAPFRE SEGUROS | C10: =+'Primas Diciembre 2024'!I54/1000 -> 1388.3075 | D10: ='Primas Diciembre 2025'!E54/1000 -> 1424.0066 | E10: =IFERROR(F10/C10,0%) -> 0.025714108 | F10: =IFERROR(D10-C10,0) -> 35.699089 | G10: ='Siniestros Diciembre 2024'!K54/1000 -> 313.50537 | H10: ='Siniestros Diciembre 2025'!H54/1000 -> 322.14935 | I10: =IFERROR(J10/G10,0%) -> 0.027572031 | J10: =IFERROR(H10-G10,0) -> 8.6439797 | K10: =IFERROR((G10/C10),0%) -> 0.22581839 | L10: =IFERROR(H10/D10,0%) -> 0.22622742 | M10: =IFERROR(N10/K10,0%) -> 0.0018113463 | N10: =L10-K10 -> 0.0004090353 | O10: =C10/$C$22 -> 0.24837256 | P10: =D10/$D$22 -> 0.24014575 | Q10: =IFERROR(R10/O10,0%) -> -0.033122847 | R10: =IFERROR(P10-O10,0) -> -0.0082268062
A11: 2 | B11: ='Primas Diciembre 2024'!$J11 -> FICOHSA SEGUROS | C11: =+'Primas Diciembre 2024'!J54/1000 -> 1032.2764 | D11: ='Primas Diciembre 2025'!F54/1000 -> 1202.4775 | E11: =IFERROR(F11/C11,0%) -> 0.16487933 | F11: =IFERROR(D11-C11,0) -> 170.20105 | G11: ='Siniestros Diciembre 2024'!M54/1000 -> 308.82472 | H11: ='Siniestros Diciembre 2025'!J54/1000 -> 288.86499 | I11: =IFERROR(J11/G11,0%) -> -0.064631243 | J11: =IFERROR(H11-G11,0) -> -19.959725 | K11: =IFERROR((G11/C11),0%) -> 0.29916863 | L11: =IFERROR(H11/D11,0%) -> 0.24022487 | M11: =IFERROR(N11/K11,0%) -> -0.19702519 | N11: =L11-K11 -> -0.058943756 | O11: =C11/$C$22 -> 0.18467748 | P11: =D11/$D$22 -> 0.20278688 | Q11: =IFERROR(R11/O11,0%) -> 0.098059589 | R11: =IFERROR(P11-O11,0) -> 0.018109398
A12: 3 | B12: ='Primas Diciembre 2024'!$L11 -> SEGUROS ATLÁNTIDA | C12: =+'Primas Diciembre 2024'!L54/1000 -> 757.75837 | D12: ='Primas Diciembre 2025'!H54/1000 -> 753.18932 | E12: =IFERROR(F12/C12,0%) -> -0.0060296916 | F12: =IFERROR(D12-C12,0) -> -4.5690493 | G12: ='Siniestros Diciembre 2024'!Q54/1000 -> 234.19851 | H12: ='Siniestros Diciembre 2025'!N54/1000 -> 283.23038 | I12: =IFERROR(J12/G12,0%) -> 0.20936031 | J12: =IFERROR(H12-G12,0) -> 49.031872 | K12: =IFERROR((G12/C12),0%) -> 0.30906753 | L12: =IFERROR(H12/D12,0%) -> 0.37604142 | M12: =IFERROR(N12/K12,0%) -> 0.21669662 | N12: =L12-K12 -> 0.066973888 | O12: =C12/$C$22 -> 0.13556534 | P12: =D12/$D$22 -> 0.12701852 | Q12: =IFERROR(R12/O12,0%) -> -0.06304576 | R12: =IFERROR(P12-O12,0) -> -0.00854682
A13: 4 | B13: ='Primas Diciembre 2024'!$G11 -> SEGUROS DAVIVIENDA | C13: =+'Primas Diciembre 2024'!G54/1000 -> 415.38705 | D13: ='Primas Diciembre 2025'!C54/1000 -> 428.32718 | E13: =IFERROR(F13/C13,0%) -> 0.031151986 | F13: =IFERROR(D13-C13,0) -> 12.940131 | G13: ='Siniestros Diciembre 2024'!G54/1000 -> 83.162574 | H13: ='Siniestros Diciembre 2025'!D54/1000 -> 124.17435 | I13: =IFERROR(J13/G13,0%) -> 0.49315178 | J13: =IFERROR(H13-G13,0) -> 41.011772 | K13: =IFERROR((G13/C13),0%) -> 0.20020502 | L13: =IFERROR(H13/D13,0%) -> 0.28990536 | M13: =IFERROR(N13/K13,0%) -> 0.44804239 | N13: =L13-K13 -> 0.089700336 | O13: =C13/$C$22 -> 0.074314042 | P13: =D13/$D$22 -> 0.072233479 | Q13: =IFERROR(R13/O13,0%) -> -0.027996896 | R13: =IFERROR(P13-O13,0) -> -0.0020805625
A14: 5 | B14: ='Primas Diciembre 2024'!$M11 -> CREFISA | C14: =+'Primas Diciembre 2024'!M54/1000 -> 364.87401 | D14: ='Primas Diciembre 2025'!I54/1000 -> 405.56715 | E14: =IFERROR(F14/C14,0%) -> 0.11152656 | F14: =IFERROR(D14-C14,0) -> 40.693141 | G14: ='Siniestros Diciembre 2024'!S54/1000 -> 115.52164 | H14: ='Siniestros Diciembre 2025'!P54/1000 -> 146.72312 | I14: =IFERROR(J14/G14,0%) -> 0.27009209 | J14: =IFERROR(H14-G14,0) -> 31.201481 | K14: =IFERROR((G14/C14),0%) -> 0.31660692 | L14: =IFERROR(H14/D14,0%) -> 0.36177269 | M14: =IFERROR(N14/K14,0%) -> 0.14265565 | N14: =L14-K14 -> 0.045165765 | O14: =C14/$C$22 -> 0.0652771 | P14: =D14/$D$22 -> 0.068395207 | Q14: =IFERROR(R14/O14,0%) -> 0.047767232 | R14: =IFERROR(P14-O14,0) -> 0.0031181064
A15: 6 | B15: ='Primas Diciembre 2024'!$N11 -> SEGUROS EQUIDAD | C15: =+'Primas Diciembre 2024'!N54/1000 -> 478.85315 | D15: ='Primas Diciembre 2025'!J54/1000 -> 387.96953 | E15: =IFERROR(F15/C15,0%) -> -0.18979435 | F15: =IFERROR(D15-C15,0) -> -90.883621 | G15: ='Siniestros Diciembre 2024'!U54/1000 -> 233.95977 | H15: ='Siniestros Diciembre 2025'!R54/1000 -> 220.15547 | I15: =IFERROR(J15/G15,0%) -> -0.0590029 | J15: =IFERROR(H15-G15,0) -> -13.804305 | K15: =IFERROR((G15/C15),0%) -> 0.48858355 | L15: =IFERROR(H15/D15,0%) -> 0.56745556 | M15: =IFERROR(N15/K15,0%) -> 0.16142994 | N15: =L15-K15 -> 0.078872012 | O15: =C15/$C$22 -> 0.085668325 | P15: =D15/$D$22 -> 0.065427528 | Q15: =IFERROR(R15/O15,0%) -> -0.23626932 | R15: =IFERROR(P15-O15,0) -> -0.020240797
A16: 7 | B16: ='Primas Diciembre 2024'!$H11 -> PALIC | C16: =+'Primas Diciembre 2024'!H54/1000 -> 369.29589 | D16: ='Primas Diciembre 2025'!D54/1000 -> 357.23276 | E16: =IFERROR(F16/C16,0%) -> -0.03266524 | F16: =IFERROR(D16-C16,0) -> -12.063139 | G16: ='Siniestros Diciembre 2024'!I54/1000 -> 37.4952 | H16: ='Siniestros Diciembre 2025'!F54/1000 -> 44.052152 | I16: =IFERROR(J16/G16,0%) -> 0.17487446 | J16: =IFERROR(H16-G16,0) -> 6.5569528 | K16: =IFERROR((G16/C16),0%) -> 0.10153159 | L16: =IFERROR(H16/D16,0%) -> 0.12331499 | M16: =IFERROR(N16/K16,0%) -> 0.21454796 | N16: =L16-K16 -> 0.021783396 | O16: =C16/$C$22 -> 0.06606819 | P16: =D16/$D$22 -> 0.060244052 | Q16: =IFERROR(R16/O16,0%) -> -0.088153442 | R16: =IFERROR(P16-O16,0) -> -0.0058241384
A17: 8 | B17: ='Primas Diciembre 2024'!$Q11 -> ASEGURADORA RURAL | C17: =+'Primas Diciembre 2024'!Q54/1000 -> 284.06315 | D17: ='Primas Diciembre 2025'!M54/1000 -> 314.23537 | E17: =IFERROR(F17/C17,0%) -> 0.10621663 | F17: =IFERROR(D17-C17,0) -> 30.172229 | G17: ='Siniestros Diciembre 2024'!AA54/1000 -> 133.92161 | H17: ='Siniestros Diciembre 2025'!X54/1000 -> 128.56251 | I17: =IFERROR(J17/G17,0%) -> -0.040016657 | J17: =IFERROR(H17-G17,0) -> -5.3590951 | K17: =IFERROR((G17/C17),0%) -> 0.47145013 | L17: =IFERROR(H17/D17,0%) -> 0.40912807 | M17: =IFERROR(N17/K17,0%) -> -0.13219227 | N17: =L17-K17 -> -0.062322062 | O17: =C17/$C$22 -> 0.050819785 | P17: =D17/$D$22 -> 0.052992935 | Q17: =IFERROR(R17/O17,0%) -> 0.042761891 | R17: =IFERROR(P17-O17,0) -> 0.0021731501
A18: 9 | B18: ='Primas Diciembre 2024'!$O11 -> SEGUROS DEL PAÍS | C18: =+'Primas Diciembre 2024'!O54/1000 -> 274.31765 | D18: ='Primas Diciembre 2025'!K54/1000 -> 301.73608 | E18: =IFERROR(F18/C18,0%) -> 0.099951413 | F18: =IFERROR(D18-C18,0) -> 27.418436 | G18: ='Siniestros Diciembre 2024'!W54/1000 -> 52.265584 | H18: ='Siniestros Diciembre 2025'!T54/1000 -> 72.595097 | I18: =IFERROR(J18/G18,0%) -> 0.38896557 | J18: =IFERROR(H18-G18,0) -> 20.329513 | K18: =IFERROR((G18/C18),0%) -> 0.19052943 | L18: =IFERROR(H18/D18,0%) -> 0.24059137 | M18: =IFERROR(N18/K18,0%) -> 0.26275175 | N18: =L18-K18 -> 0.05006194 | O18: =C18/$C$22 -> 0.049076284 | P18: =D18/$D$22 -> 0.050885043 | Q18: =IFERROR(R18/O18,0%) -> 0.036856062 | R18: =IFERROR(P18-O18,0) -> 0.0018087586
A19: 10 | B19: ='Primas Diciembre 2024'!$P11 -> SEGUROS LAFISE | C19: =+'Primas Diciembre 2024'!P54/1000 -> 182.67784 | D19: ='Primas Diciembre 2025'!L54/1000 -> 175.56464 | E19: =IFERROR(F19/C19,0%) -> -0.038938485 | F19: =IFERROR(D19-C19,0) -> -7.1131984 | G19: ='Siniestros Diciembre 2024'!Y54/1000 -> 52.614254 | H19: ='Siniestros Diciembre 2025'!V54/1000 -> 66.059484 | I19: =IFERROR(J19/G19,0%) -> 0.25554348 | J19: =IFERROR(H19-G19,0) -> 13.44523 | K19: =IFERROR((G19/C19),0%) -> 0.28801662 | L19: =IFERROR(H19/D19,0%) -> 0.37626873 | M19: =IFERROR(N19/K19,0%) -> 0.30641323 | N19: =L19-K19 -> 0.088252103 | O19: =C19/$C$22 -> 0.032681637 | P19: =D19/$D$22 -> 0.029607378 | Q19: =IFERROR(R19/O19,0%) -> -0.094066842 | R19: =IFERROR(P19-O19,0) -> -0.0030742583
A20: 11 | B20: ='Primas Diciembre 2024'!$R11 -> ASSA CIA. DE SEGUROS | C20: =+'Primas Diciembre 2024'!R54/1000 -> 18.600111 | D20: ='Primas Diciembre 2025'!N54/1000 -> 157.07301 | E20: =IFERROR(F20/C20,0%) -> 7.4447352 | F20: =IFERROR(D20-C20,0) -> 138.4729 | G20: ='Siniestros Diciembre 2024'!AC54/1000 -> 7.8655091 | H20: ='Siniestros Diciembre 2025'!Z54/1000 -> 25.169193 | I20: =IFERROR(J20/G20,0%) -> 2.1999445 | J20: =IFERROR(H20-G20,0) -> 17.303684 | K20: =IFERROR((G20/C20),0%) -> 0.42287431 | L20: =IFERROR(H20/D20,0%) -> 0.16023881 | M20: =IFERROR(N20/K20,0%) -> -0.62107225 | N20: =L20-K20 -> -0.2626355 | O20: =C20/$C$22 -> 0.003327618 | P20: =D20/$D$22 -> 0.026488934 | Q20: =IFERROR(R20/O20,0%) -> 6.9603288 | R20: =IFERROR(P20-O20,0) -> 0.023161316
A21: 12 | B21: ='Primas Diciembre 2024'!$K11 -> SEGUROS CONTINENTAL | C21: =+'Primas Diciembre 2024'!K54/1000 -> 23.206099 | D21: ='Primas Diciembre 2025'!G54/1000 -> 22.38068 | E21: =IFERROR(F21/C21,0%) -> -0.035569075 | F21: =IFERROR(D21-C21,0) -> -0.82541949 | G21: ='Siniestros Diciembre 2024'!O54/1000 -> 17.353321 | H21: ='Siniestros Diciembre 2025'!L54/1000 -> 8.2414875 | I21: =IFERROR(J21/G21,0%) -> -0.52507723 | J21: =IFERROR(H21-G21,0) -> -9.1118339 | K21: =IFERROR((G21/C21),0%) -> 0.7477914 | L21: =IFERROR(H21/D21,0%) -> 0.36824116 | M21: =IFERROR(N21/K21,0%) -> -0.50756165 | N21: =L21-K21 -> -0.37955024 | O21: =C21/$C$22 -> 0.0041516437 | P21: =D21/$D$22 -> 0.0037742979 | Q21: =IFERROR(R21/O21,0%) -> -0.090890708 | R21: =IFERROR(P21-O21,0) -> -0.00037734583
A22: Total general | C22: =SUM(C10:C21) -> 5589.6173 | D22: =SUM(D10:D21) -> 5929.7598 | E22: =IFERROR(F22/C22,0%) -> 0.060852565 | F22: =D22-C22 -> 340.14255 | G22: =SUM(G10:G21) -> 1590.688 | H22: =SUM(H10:H21) -> 1729.9776 | I22: =IFERROR(J22/G22,0%) -> 0.087565582 | J22: =H22-G22 -> 139.28952 | K22: =IFERROR((G22/C22),0%) -> 0.28457906 | L22: =IFERROR(H22/D22,0%) -> 0.29174497 | M22: =IFERROR(N22/K22,0%) -> 0.025180706 | N22: =L22-K22 -> 0.0071659017
A24: ='1. Ramos Totales'!A$24 -> Inflación Interanual Diciembre 2025 | E24: ='1. Ramos Totales'!$D$24 -> 0.0498 | G24: ='1. Ramos Totales'!$F$24 -> Inflación Acumulada Diciembre 2025 | J24: ='1. Ramos Totales'!$J$24 -> 0.0498
A25: Crecimiento Real | E25: =E22-E24 -> 0.011052565

Sheet 3. Accidentes y Enfermedades
A1: Sector Asegurador Hondureño
A2: Situación de Primas y Siniestros por Ramo
A3: ='1. Ramos Totales'!A3 -> Al 31 de diciembre de 2025
A4: (Valores en millones de Lempiras y Porcentajes)
A6: 3. Accidentes y Enfermedades
A8: No. | B8: Compañía | C8: Primas | G8: Siniestros | K8: Siniestros/Primas | O8: Participación de mercado
C9: ='1. Ramos Totales'!$B$9 -> 45657 | D9: ='1. Ramos Totales'!$C$9 -> 46022 | E9: Relativa | F9: Absoluta | G9: ='1. Ramos Totales'!$B$9 -> 45657 | H9: ='1. Ramos Totales'!$C$9 -> 46022 | I9: Relativa | J9: Absoluta | K9: ='1. Ramos Totales'!$B$9 -> 45657 | L9: ='1. Ramos Totales'!$C$9 -> 46022 | M9: Relativa | N9: Absoluta | O9: ='1. Ramos Totales'!$B$9 -> 45657 | P9: ='1. Ramos Totales'!$C$9 -> 46022 | Q9: Relativa | R9: Absoluta
A10: 1 | B10: ='Primas Diciembre 2024'!J11 -> FICOHSA SEGUROS | C10: =('Primas Diciembre 2024'!J12)/1000 -> 914.25207 | D10: =('Primas Diciembre 2025'!F12)/1000 -> 1042.9622 | E10: =IFERROR(F10/C10,0%) -> 0.14078191 | F10: =IFERROR(D10-C10,0) -> 128.71016 | G10: =('Siniestros Diciembre 2024'!M12)/1000 -> 657.16551 | H10: =('Siniestros Diciembre 2025'!J12)/1000 -> 756.24702 | I10: =IFERROR(J10/G10,0%) -> 0.15077101 | J10: =IFERROR(H10-G10,0) -> 99.081506 | K10: =IFERROR((G10/C10),0%) -> 0.71880123 | L10: =IFERROR(H10/D10,0%) -> 0.72509531 | M10: =IFERROR(N10/K10,0%) -> 0.0087563568 | N10: =IFERROR(L10-K10,0) -> 0.00629408 | O10: =C10/$C$22 -> 0.24925509 | P10: =D10/$D$22 -> 0.25752112 | Q10: =IFERROR(R10/O10,0%) -> 0.033162942 | R10: =IFERROR(P10-O10,0) -> 0.008266032
A11: 2 | B11: ='Primas Diciembre 2024'!H11 -> PALIC | C11: =('Primas Diciembre 2024'!H12)/1000 -> 673.59016 | D11: =('Primas Diciembre 2025'!D12)/1000 -> 713.44266 | E11: =IFERROR(F11/C11,0%) -> 0.05916431 | F11: =IFERROR(D11-C11,0) -> 39.852497 | G11: =('Siniestros Diciembre 2024'!I12)/1000 -> 429.7557 | H11: =('Siniestros Diciembre 2025'!F12)/1000 -> 454.57002 | I11: =IFERROR(J11/G11,0%) -> 0.057740529 | J11: =IFERROR(H11-G11,0) -> 24.814322 | K11: =IFERROR((G11/C11),0%) -> 0.63800769 | L11: =IFERROR(H11/D11,0%) -> 0.63715005 | M11: =IFERROR(N11/K11,0%) -> -0.0013442491 | N11: =IFERROR(L11-K11,0) -> -0.00085764124 | O11: =C11/$C$22 -> 0.18364276 | P11: =D11/$D$22 -> 0.1761584 | Q11: =IFERROR(R11/O11,0%) -> -0.040755029 | R11: =IFERROR(P11-O11,0) -> -0.007484366
A12: 3 | B12: ='Primas Diciembre 2024'!I11 -> MAPFRE SEGUROS | C12: =('Primas Diciembre 2024'!I12)/1000 -> 624.003 | D12: =('Primas Diciembre 2025'!E12)/1000 -> 633.09547 | E12: =IFERROR(F12/C12,0%) -> 0.014571204 | F12: =IFERROR(D12-C12,0) -> 9.0924752 | G12: =('Siniestros Diciembre 2024'!K12)/1000 -> 385.53207 | H12: =('Siniestros Diciembre 2025'!H12)/1000 -> 355.23353 | I12: =IFERROR(J12/G12,0%) -> -0.078588904 | J12: =IFERROR(H12-G12,0) -> -30.298543 | K12: =IFERROR((G12/C12),0%) -> 0.61783689 | L12: =IFERROR(H12/D12,0%) -> 0.56110578 | M12: =IFERROR(N12/K12,0%) -> -0.09182215 | N12: =IFERROR(L12-K12,0) -> -0.056731112 | O12: =C12/$C$22 -> 0.17012367 | P12: =D12/$D$22 -> 0.15631962 | Q12: =IFERROR(R12/O12,0%) -> -0.081141314 | R12: =IFERROR(P12-O12,0) -> -0.013804059
A13: 4 | B13: ='Primas Diciembre 2024'!M11 -> CREFISA | C13: =('Primas Diciembre 2024'!M12)/1000 -> 529.58263 | D13: =('Primas Diciembre 2025'!I12)/1000 -> 568.72902 | E13: =IFERROR(F13/C13,0%) -> 0.073919318 | F13: =IFERROR(D13-C13,0) -> 39.146387 | G13: =('Siniestros Diciembre 2024'!S12)/1000 -> 347.09725 | H13: =('Siniestros Diciembre 2025'!P12)/1000 -> 368.88942 | I13: =IFERROR(J13/G13,0%) -> 0.062784054 | J13: =IFERROR(H13-G13,0) -> 21.792172 | K13: =IFERROR((G13/C13),0%) -> 0.6554166 | L13: =IFERROR(H13/D13,0%) -> 0.64862071 | M13: =IFERROR(N13/K13,0%) -> -0.010368809 | N13: =IFERROR(L13-K13,0) -> -0.0067958893 | O13: =C13/$C$22 -> 0.14438159 | P13: =D13/$D$22 -> 0.14042669 | Q13: =IFERROR(R13/O13,0%) -> -0.027391977 | R13: =IFERROR(P13-O13,0) -> -0.0039548971
A14: 5 | B14: ='Primas Diciembre 2024'!L11 -> SEGUROS ATLÁNTIDA | C14: =('Primas Diciembre 2024'!L12)/1000 -> 397.55087 | D14: =('Primas Diciembre 2025'!H12)/1000 -> 463.16415 | E14: =IFERROR(F14/C14,0%) -> 0.16504372 | F14: =IFERROR(D14-C14,0) -> 65.613274 | G14: =('Siniestros Diciembre 2024'!Q12)/1000 -> 355.48088 | H14: =('Siniestros Diciembre 2025'!N12)/1000 -> 384.35203 | I14: =IFERROR(J14/G14,0%) -> 0.081217167 | J14: =IFERROR(H14-G14,0) -> 28.87115 | K14: =IFERROR((G14/C14),0%) -> 0.89417708 | L14: =IFERROR(H14/D14,0%) -> 0.82983976 | M14: =IFERROR(N14/K14,0%) -> -0.071951421 | N14: =IFERROR(L14-K14,0) -> -0.064337312 | O14: =C14/$C$22 -> 0.1083854 | P14: =D14/$D$22 -> 0.11436133 | Q14: =IFERROR(R14/O14,0%) -> 0.055135938 | R14: =IFERROR(P14-O14,0) -> 0.0059759308
A15: 6 | B15: ='Primas Diciembre 2024'!O11 -> SEGUROS DEL PAÍS | C15: =('Primas Diciembre 2024'!O12)/1000 -> 146.23899 | D15: =('Primas Diciembre 2025'!K12)/1000 -> 150.60871 | E15: =IFERROR(F15/C15,0%) -> 0.029880665 | F15: =IFERROR(D15-C15,0) -> 4.3697184 | G15: =('Siniestros Diciembre 2024'!W12)/1000 -> 80.950222 | H15: =('Siniestros Diciembre 2025'!T12)/1000 -> 80.919353 | I15: =IFERROR(J15/G15,0%) -> -0.00038132854 | J15: =IFERROR(H15-G15,0) -> -0.03086863 | K15: =IFERROR((G15/C15),0%) -> 0.55354746 | L15: =IFERROR(H15/D15,0%) -> 0.53728203 | M15: =IFERROR(N15/K15,0%) -> -0.029383981 | N15: =IFERROR(L15-K15,0) -> -0.016265428 | O15: =C15/$C$22 -> 0.039869544 | P15: =D15/$D$22 -> 0.037187276 | Q15: =IFERROR(R15/O15,0%) -> -0.067276116 | R15: =IFERROR(P15-O15,0) -> -0.002682268
A16: 7 | B16: ='Primas Diciembre 2024'!R11 -> ASSA CIA. DE SEGUROS | C16: =('Primas Diciembre 2024'!R12)/1000 -> 89.863386 | D16: =('Primas Diciembre 2025'!N12)/1000 -> 125.78472 | E16: =IFERROR(F16/C16,0%) -> 0.39973268 | F16: =IFERROR(D16-C16,0) -> 35.921332 | G16: =('Siniestros Diciembre 2024'!AC12)/1000 -> 51.687813 | H16: =('Siniestros Diciembre 2025'!Z12)/1000 -> 79.363936 | I16: =IFERROR(J16/G16,0%) -> 0.53544776 | J16: =IFERROR(H16-G16,0) -> 27.676124 | K16: =IFERROR((G16/C16),0%) -> 0.57518212 | L16: =IFERROR(H16/D16,0%) -> 0.63095055 | M16: =IFERROR(N16/K16,0%) -> 0.096957855 | N16: =IFERROR(L16-K16,0) -> 0.055768424 | O16: =C16/$C$22 -> 0.024499705 | P16: =D16/$D$22 -> 0.031057905 | Q16: =IFERROR(R16/O16,0%) -> 0.26768484 | R16: =IFERROR(P16-O16,0) -> 0.0065581996
A17: 8 | B17: ='Primas Diciembre 2024'!G11 -> SEGUROS DAVIVIENDA | C17: =('Primas Diciembre 2024'!G12)/1000 -> 90.366199 | D17: =('Primas Diciembre 2025'!C12)/1000 -> 112.31359 | E17: =IFERROR(F17/C17,0%) -> 0.24287165 | F17: =IFERROR(D17-C17,0) -> 21.947388 | G17: =('Siniestros Diciembre 2024'!G12)/1000 -> 62.357868 | H17: =('Siniestros Diciembre 2025'!D12)/1000 -> 88.201256 | I17: =IFERROR(J17/G17,0%) -> 0.41443668 | J17: =IFERROR(H17-G17,0) -> 25.843388 | K17: =IFERROR((G17/C17),0%) -> 0.69005744 | L17: =IFERROR(H17/D17,0%) -> 0.78531242 | M17: =IFERROR(N17/K17,0%) -> 0.13803921 | N17: =IFERROR(L17-K17,0) -> 0.095254986 | O17: =C17/$C$22 -> 0.024636789 | P17: =D17/$D$22 -> 0.027731705 | Q17: =IFERROR(R17/O17,0%) -> 0.12562175 | R17: =IFERROR(P17-O17,0) -> 0.0030949165
A18: 9 | B18: ='Primas Diciembre 2024'!Q11 -> ASEGURADORA RURAL | C18: =('Primas Diciembre 2024'!Q12)/1000 -> 49.346352 | D18: =('Primas Diciembre 2025'!M12)/1000 -> 89.300424 | E18: =IFERROR(F18/C18,0%) -> 0.80966619 | F18: =IFERROR(D18-C18,0) -> 39.954073 | G18: =('Siniestros Diciembre 2024'!AA12)/1000 -> 56.99302 | H18: =('Siniestros Diciembre 2025'!X12)/1000 -> 67.768249 | I18: =IFERROR(J18/G18,0%) -> 0.18906224 | J18: =IFERROR(H18-G18,0) -> 10.775228 | K18: =IFERROR((G18/C18),0%) -> 1.1549592 | L18: =IFERROR(H18/D18,0%) -> 0.75887936 | M18: =IFERROR(N18/K18,0%) -> -0.34293836 | N18: =IFERROR(L18-K18,0) -> -0.39607979 | O18: =C18/$C$22 -> 0.013453433 | P18: =D18/$D$22 -> 0.022049452 | Q18: =IFERROR(R18/O18,0%) -> 0.63894608 | R18: =IFERROR(P18-O18,0) -> 0.0085960185
A19: 10 | B19: ='Primas Diciembre 2024'!K11 -> SEGUROS CONTINENTAL | C19: =('Primas Diciembre 2024'!K12)/1000 -> 72.925601 | D19: =('Primas Diciembre 2025'!G12)/1000 -> 74.618928 | E19: =IFERROR(F19/C19,0%) -> 0.02321993 | F19: =IFERROR(D19-C19,0) -> 1.6933273 | G19: =('Siniestros Diciembre 2024'!O12)/1000 -> 38.34444 | H19: =('Siniestros Diciembre 2025'!L12)/1000 -> 74.883833 | I19: =IFERROR(J19/G19,0%) -> 0.95292544 | J19: =IFERROR(H19-G19,0) -> 36.539393 | K19: =IFERROR((G19/C19),0%) -> 0.52580219 | L19: =IFERROR(H19/D19,0%) -> 1.0035501 | M19: =IFERROR(N19/K19,0%) -> 0.9086077 | N19: =IFERROR(L19-K19,0) -> 0.47774792 | O19: =C19/$C$22 -> 0.01988191 | P19: =D19/$D$22 -> 0.018424397 | Q19: =IFERROR(R19/O19,0%) -> -0.073308491 | R19: =IFERROR(P19-O19,0) -> -0.0014575128
A20: 11 | B20: ='Primas Diciembre 2024'!N11 -> SEGUROS EQUIDAD | C20: =('Primas Diciembre 2024'!N12)/1000 -> 75.339583 | D20: =('Primas Diciembre 2025'!J12)/1000 -> 69.227719 | E20: =IFERROR(F20/C20,0%) -> -0.081124215 | F20: =IFERROR(D20-C20,0) -> -6.1118646 | G20: =('Siniestros Diciembre 2024'!U12)/1000 -> 56.215273 | H20: =('Siniestros Diciembre 2025'!R12)/1000 -> 49.006646 | I20: =IFERROR(J20/G20,0%) -> -0.12823253 | J20: =IFERROR(H20-G20,0) -> -7.208627 | K20: =IFERROR((G20/C20),0%) -> 0.74615854 | L20: =IFERROR(H20/D20,0%) -> 0.70790497 | M20: =IFERROR(N20/K20,0%) -> -0.051267342 | N20: =IFERROR(L20-K20,0) -> -0.038253565 | O20: =C20/$C$22 -> 0.02054004 | P20: =D20/$D$22 -> 0.017093236 | Q20: =IFERROR(R20/O20,0%) -> -0.16780903 | R20: =IFERROR(P20-O20,0) -> -0.0034468042
A21: 12 | B21: ='Primas Diciembre 2024'!P11 -> SEGUROS LAFISE | C21: =('Primas Diciembre 2024'!P12)/1000 -> 4.8785932 | D21: =('Primas Diciembre 2025'!L12)/1000 -> 6.7589499 | E21: =IFERROR(F21/C21,0%) -> 0.38543012 | F21: =IFERROR(D21-C21,0) -> 1.8803567 | G21: =('Siniestros Diciembre 2024'!Y12)/1000 -> 2.3145313 | H21: =('Siniestros Diciembre 2025'!V12)/1000 -> 4.8600086 | I21: =IFERROR(J21/G21,0%) -> 1.0997809 | J21: =IFERROR(H21-G21,0) -> 2.5454773 | K21: =IFERROR((G21/C21),0%) -> 0.47442597 | L21: =IFERROR(H21/D21,0%) -> 0.71904788 | M21: =IFERROR(N21/K21,0%) -> 0.5156166 | N21: =IFERROR(L21-K21,0) -> 0.24462191 | O21: =C21/$C$22 -> 0.0013300645 | P21: =D21/$D$22 -> 0.0016688738 | Q21: =IFERROR(R21/O21,0%) -> 0.25473155 | R21: =IFERROR(P21-O21,0) -> 0.00033880938
A22: Total general | C22: =SUM(C10:C21) -> 3667.9374 | D22: =SUM(D10:D21) -> 4050.0066 | E22: =D22/C22-1 -> 0.10416457 | F22: =D22-C22 -> 382.06912 | G22: =SUM(G10:G21) -> 2523.8946 | H22: =SUM(H10:H21) -> 2764.2953 | I22: =H22/G22-1 -> 0.095249906 | J22: =H22-G22 -> 240.40072 | K22: =IFERROR((G22/C22),0%) -> 0.68809641 | L22: =IFERROR(H22/D22,0%) -> 0.68254094 | M22: =IFERROR(N22/K22,0%) -> -0.0080736723 | N22: =L22-K22 -> -0.0055554649
A24: ='1. Ramos Totales'!A$24 -> Inflación Interanual Diciembre 2025 | E24: ='1. Ramos Totales'!$D$24 -> 0.0498 | G24: ='1. Ramos Totales'!$F$24 -> Inflación Acumulada Diciembre 2025 | J24: ='1. Ramos Totales'!$J$24 -> 0.0498
A25: Crecimiento Real | E25: =E22-E24 -> 0.054364569

Sheet 3.1 Salud y Hospitalización
A1: Sector Asegurador Hondureño
A2: Situación de Primas y Siniestros por Ramo
A3: ='1. Ramos Totales'!A3 -> Al 31 de diciembre de 2025
A4: (Valores en millones de Lempiras y Porcentajes)
A6: 3.1 Salud y Hospitalización
A8: No. | B8: Compañía | C8: Primas | G8: Siniestros | K8: Siniestros/Primas | O8: Participación de mercado
C9: ='1. Ramos Totales'!$B$9 -> 45657 | D9: ='1. Ramos Totales'!$C$9 -> 46022 | E9: Relativa | F9: Absoluta | G9: ='1. Ramos Totales'!$B$9 -> 45657 | H9: ='1. Ramos Totales'!$C$9 -> 46022 | I9: Relativa | J9: Absoluta | K9: ='1. Ramos Totales'!$B$9 -> 45657 | L9: ='1. Ramos Totales'!$C$9 -> 46022 | M9: Relativa | N9: Absoluta | O9: ='1. Ramos Totales'!$B$9 -> 45657 | P9: ='1. Ramos Totales'!$C$9 -> 46022 | Q9: Relativa | R9: Absoluta
A10: 1 | B10: ='Primas Diciembre 2024'!J11 -> FICOHSA SEGUROS | C10: =('Primas Diciembre 2024'!J15)/1000 -> 869.41191 | D10: =('Primas Diciembre 2025'!F15)/1000 -> 954.91969 | E10: =IFERROR(F10/C10,0%) -> 0.098351293 | F10: =IFERROR(D10-C10,0) -> 85.507785 | G10: =('Siniestros Diciembre 2024'!M15)/1000 -> 643.68816 | H10: =('Siniestros Diciembre 2025'!J15)/1000 -> 727.01661 | I10: =IFERROR(J10/G10,0%) -> 0.12945469 | J10: =IFERROR(H10-G10,0) -> 83.32845 | K10: =IFERROR((G10/C10),0%) -> 0.74037191 | L10: =IFERROR(H10/D10,0%) -> 0.76133796 | M10: =IFERROR(N10/K10,0%) -> 0.028318258 | N10: =IFERROR(L10-K10,0) -> 0.020966043 | O10: =C10/$C$22 -> 0.26783641 | P10: =D10/$D$22 -> 0.27066478 | Q10: =IFERROR(R10/O10,0%) -> 0.010560081 | R10: =IFERROR(P10-O10,0) -> 0.0028283741
A11: 2 | B11: ='Primas Diciembre 2024'!H11 -> PALIC | C11: =('Primas Diciembre 2024'!H15)/1000 -> 667.89291 | D11: =('Primas Diciembre 2025'!D15)/1000 -> 707.39371 | E11: =IFERROR(F11/C11,0%) -> 0.059142415 | F11: =IFERROR(D11-C11,0) -> 39.5008 | G11: =('Siniestros Diciembre 2024'!I15)/1000 -> 429.7557 | H11: =('Siniestros Diciembre 2025'!F15)/1000 -> 454.57002 | I11: =IFERROR(J11/G11,0%) -> 0.057740529 | J11: =IFERROR(H11-G11,0) -> 24.814322 | K11: =IFERROR((G11/C11),0%) -> 0.64345001 | L11: =IFERROR(H11/D11,0%) -> 0.64259834 | M11: =IFERROR(N11/K11,0%) -> -0.0013236046 | N11: =IFERROR(L11-K11,0) -> -0.00085167338 | O11: =C11/$C$22 -> 0.20575522 | P11: =D11/$D$22 -> 0.20050541 | Q11: =IFERROR(R11/O11,0%) -> -0.025514832 | R11: =IFERROR(P11-O11,0) -> -0.0052498099
A12: 3 | B12: ='Primas Diciembre 2024'!M11 -> CREFISA | C12: =('Primas Diciembre 2024'!M15)/1000 -> 477.07633 | D12: =('Primas Diciembre 2025'!I15)/1000 -> 513.55569 | E12: =IFERROR(F12/C12,0%) -> 0.076464416 | F12: =IFERROR(D12-C12,0) -> 36.479363 | G12: =('Siniestros Diciembre 2024'!S15)/1000 -> 336.48771 | H12: =('Siniestros Diciembre 2025'!P15)/1000 -> 359.60654 | I12: =IFERROR(J12/G12,0%) -> 0.068706332 | J12: =IFERROR(H12-G12,0) -> 23.118836 | K12: =IFERROR((G12/C12),0%) -> 0.7053121 | L12: =IFERROR(H12/D12,0%) -> 0.70022891 | M12: =IFERROR(N12/K12,0%) -> -0.007207005 | N12: =IFERROR(L12-K12,0) -> -0.0050831879 | O12: =C12/$C$22 -> 0.14697109 | P12: =D12/$D$22 -> 0.14556349 | Q12: =IFERROR(R12/O12,0%) -> -0.0095773783 | R12: =IFERROR(P12-O12,0) -> -0.0014075977
A13: 4 | B13: ='Primas Diciembre 2024'!L11 -> SEGUROS ATLÁNTIDA | C13: =('Primas Diciembre 2024'!L15)/1000 -> 382.18166 | D13: =('Primas Diciembre 2025'!H15)/1000 -> 446.33783 | E13: =IFERROR(F13/C13,0%) -> 0.16786826 | F13: =IFERROR(D13-C13,0) -> 64.15617 | G13: =('Siniestros Diciembre 2024'!Q15)/1000 -> 351.03241 | H13: =('Siniestros Diciembre 2025'!N15)/1000 -> 379.1183 | I13: =IFERROR(J13/G13,0%) -> 0.080009405 | J13: =IFERROR(H13-G13,0) -> 28.085894 | K13: =IFERROR((G13/C13),0%) -> 0.91849622 | L13: =IFERROR(H13/D13,0%) -> 0.84939765 | M13: =IFERROR(N13/K13,0%) -> -0.075230109 | N13: =IFERROR(L13-K13,0) -> -0.069098571 | O13: =C13/$C$22 -> 0.11773725 | P13: =D13/$D$22 -> 0.12651109 | Q13: =IFERROR(R13/O13,0%) -> 0.074520558 | R13: =IFERROR(P13-O13,0) -> 0.0087738453
